<?xml version="1.0"?>
<robot name="Puzzlebot_Jetson_Lidar_Ed.">

  <!-- MATERIALS -->
  <material name="white">
    <color rgba="1 1 1 1"/>
  </material>
  <material name="black">
    <color rgba="0 0 0 1"/>
  </material>
  <material name="blue">
    <color rgba="0 0 0.8 1"/>
  </material>

  <!-- BASE FOOTPRINT (Root) -->
  <link name="base_footprint"/>

  <!-- BASE LINK (Chassis) -->
  <link name="base_link">
    <visual>
      <origin xyz="0 0 0" rpy="1.5708 0 1.5708"/>
      <geometry>
        <mesh filename="package://puzzlebot_sim/meshes/Puzzlebot_Jetson_Lidar_Edition_Base.stl"/>
      </geometry>
      <material name="white"/>
    </visual>
  </link>

  <joint name="base_link_joint" type="fixed">
    <parent link="base_footprint"/>
    <child link="base_link"/>
    <origin xyz="0 0 0.05" rpy="0 0 0"/>
  </joint>

  <!-- RIGHT WHEEL -->
  <link name="wheel_r_link">
    <visual>
      <origin xyz="0 0 0" rpy="1.5708 0 0"/>
      <geometry>
        <mesh filename="package://puzzlebot_sim/meshes/Puzzlebot_Wheel.stl"/>
      </geometry>
      <material name="black"/>
    </visual>
  </link>

  <joint name="wheel_r_joint" type="continuous">
    <parent link="base_link"/>
    <child link="wheel_r_link"/>
    <origin xyz="0.052 -0.095 -0.0025" rpy="0 0 0"/>
    <axis xyz="0 1 0"/>
  </joint>

  <!-- LEFT WHEEL -->
  <link name="wheel_l_link">
    <visual>
      <origin xyz="0 0 0" rpy="-1.5708 0 0"/>
      <geometry>
        <mesh filename="package://puzzlebot_sim/meshes/Puzzlebot_Wheel.stl"/>
      </geometry>
      <material name="black"/>
    </visual>
  </link>

  <joint name="wheel_l_joint" type="continuous">
    <parent link="base_link"/>
    <child link="wheel_l_link"/>
    <origin xyz="0.052 0.095 -0.0025" rpy="0 0 0"/>
    <axis xyz="0 1 0"/>
  </joint>

  <!-- CASTER WHEEL -->
  <link name="caster_link">
    <visual>
      <origin xyz="0 0 0" rpy="0 0 0"/>
      <geometry>
        <mesh filename="package://puzzlebot_sim/meshes/Puzzlebot_Caster_Wheel.stl"/>
      </geometry>
      <material name="black"/>
    </visual>
  </link>

  <joint name="caster_joint" type="fixed">
    <parent link="base_link"/>
    <child link="caster_link"/>
    <origin xyz="-0.095 0 -0.03" rpy="0 0 0"/>
  </joint>

</robot>